<?xml version="1.0" ?>
<!-- =================================================================================== -->
<!-- |    This document was autogenerated by xacro from /home/promise/PA_robot_urdf/urdf/romr_robot_patched.xacro | -->
<!-- |    EDITING THIS FILE BY HAND IS NOT RECOMMENDED                                 | -->
<!-- =================================================================================== -->
<robot name="romr_ros">
  <material name="white">
    <color rgba="1 1 1 1"/>
  </material>
  <material name="yellow">
    <color rgba="1 1 0.5 1"/>
  </material>
  <material name="black">
    <color rgba="0 0 0 1"/>
  </material>
  <material name="orange">
    <color rgba="1 0.3 0.1 1"/>
  </material>
  <material name="blue">
    <color rgba="0.2 0.2 1 1"/>
  </material>
  <material name="grey">
    <color rgba="0.4 0.4 0.4 1"/>
  </material>
  <gazebo reference="base_link">
    <material>Gazebo/White</material>
  </gazebo>
  <gazebo reference="camerad435i_link">
    <material>Gazebo/White</material>
  </gazebo>
  <gazebo reference="imu_link">
    <material>Gazebo/Black</material>
  </gazebo>
  <gazebo reference="rightwheel_link">
    <material>Gazebo/Black</material>
  </gazebo>
  <gazebo reference="leftwheel_link">
    <material>Gazebo/Black</material>
  </gazebo>
  <gazebo reference="casterwheel_link">
    <material>Gazebo/Blue</material>
  </gazebo>
  <gazebo reference="lidar_link">
    <material>Gazebo/LightBlueLaser</material>
  </gazebo>
  <gazebo reference="base_link">
    <mu1>1.0</mu1>
    <mu2>1.0</mu2>
    <selfCollide>true</selfCollide>
    <gravity>true</gravity>
  </gazebo>
  <gazebo reference="rightwheel_link">
    <mu1>1000.0</mu1>
    <mu2>1000.0</mu2>
    <selfCollide>true</selfCollide>
  </gazebo>
  <gazebo reference="leftwheel_link">
    <mu1>1000.0</mu1>
    <mu2>1000.0</mu2>
    <selfCollide>true</selfCollide>
  </gazebo>
  <gazebo reference="casterwheel_link">
    <mu1>0.01</mu1>
    <mu2>0.01</mu2>
    <selfCollide>true</selfCollide>
  </gazebo>
  <gazebo reference="lidar_link">
    <mu1>1.0</mu1>
    <mu2>1.0</mu2>
    <selfCollide>true</selfCollide>
  </gazebo>
  <gazebo reference="camerad435i_link">
    <mu1>1.0</mu1>
    <mu2>1.0</mu2>
    <selfCollide>true</selfCollide>
  </gazebo>
  <gazebo reference="camerat265_link">
    <mu1>1.0</mu1>
    <mu2>1.0</mu2>
    <selfCollide>true</selfCollide>
  </gazebo>
  <gazebo reference="imu_link">
    <mu1>1.0</mu1>
    <mu2>1.0</mu2>
    <selfCollide>true</selfCollide>
  </gazebo>
  <!-- ************ romr differential drive plugin ************* -->
  <gazebo>
    <plugin filename="libgazebo_ros_diff_drive.so" name="differential_drive_controller">
      <updateRate>50</updateRate>
      <leftJoint>leftwheel_joint</leftJoint>
      <rightJoint>rightwheel_joint</rightJoint>
      <wheelSeparation>0.30</wheelSeparation>
      <wheelDiameter>0.1610</wheelDiameter>
      <wheelAcceleration>1.0</wheelAcceleration>
      <wheelTorque>20</wheelTorque>
      <commandTopic>cmd_vel</commandTopic>
      <odometryTopic>odom</odometryTopic>
      <odometryFrame>odom</odometryFrame>
      <robotBaseFrame>base_link</robotBaseFrame>
      <odometrySource>1</odometrySource>
      <publishWheelTF>false</publishWheelTF>
      <publishWheelJointState>false</publishWheelJointState>
      <publishOdom>true</publishOdom>
      <publishTf>1</publishTf>
      <publishOdomTF>true</publishOdomTF>
      <publishWheelJointState>true</publishWheelJointState>
      <legacyMode>false</legacyMode>
      <alwaysOn>true</alwaysOn>
      <!-- <odometrySource>world</odometrySource> -->
      <rosDebugLevel>Debug</rosDebugLevel>
      <broadcastTF>true</broadcastTF>
    </plugin>
  </gazebo>
  <!-- ***********  romr lidar sensor plugin ************* -->
  <gazebo reference="lidar_link">
    <sensor name="rplidar_a2" type="ray">
      <pose>0 0 0 0 0 0</pose>
      <visualize>false</visualize>
      <update_rate>10</update_rate>
      <ray>
        <scan>
          <horizontal>
            <samples>720</samples>
            <resolution>1</resolution>
            <min_angle>-3.14159</min_angle>
            <max_angle>3.14159</max_angle>
          </horizontal>
        </scan>
        <range>
          <min>0.15</min>
          <max>16.0</max>
          <resolution>0.1</resolution>
        </range>
        <noise>
          <type>gaussian</type>
          <mean>0.0</mean>
          <stddev>0.01</stddev>
        </noise>
      </ray>
      <plugin filename="libgazebo_ros_laser.so" name="gazebo_ros_head_hokuyo_controller">
        <topicName>/scan</topicName>
        <frameName>lidar_link</frameName>
      </plugin>
    </sensor>
  </gazebo>
  <!-- ************* IMU sensor plugin ***************** -->
  <gazebo reference="imu_link">
    <gravity>true</gravity>
    <sensor name="imu_sensor" type="imu">
      <always_on>true</always_on>
      <update_rate>10</update_rate>
      <visualize>true</visualize>
      <topic>__default_topic__</topic>
      <plugin filename="libgazebo_ros_imu_sensor.so" name="imu_plugin">
        <topicName>imu</topicName>
        <bodyName>imu_link</bodyName>
        <updateRateHZ>10.0</updateRateHZ>
        <gaussianNoise>0.0</gaussianNoise>
        <xyzOffset>0 0 0</xyzOffset>
        <rpyOffset>0 0 0</rpyOffset>
        <frameName>imu_link</frameName>
        <initialOrientationAsReference>false</initialOrientationAsReference>
      </plugin>
      <pose>0 0 0 0 0 0</pose>
    </sensor>
  </gazebo>
  <!-- ********************* Camera sensor plugin ******************* -->
  <!--
<gazebo reference="camerat265_link">
  <sensor type="camera" name="camera1">
    <update_rate>30.0</update_rate>
    <camera name="head">
      <horizontal_fov>1.3962634</horizontal_fov>
      <image>
        <width>640</width>
        <height>320</height>
        <format>R8G8B8</format>  -->
  <!-- 8 bits RED, 8 bits Green, and 8 bits Blue -->
  <!-- </image>
      <clip>
        <near>0.02</near>
        <far>300</far>
      </clip>
      <noise>
        <type>gaussian</type>
        <mean>0.0</mean>
        <stddev>0.007</stddev>
    </noise>
    </camera> -->
  <!-- <plugin name="camera_controller" filename="libgazebo_ros_camera.so">
      <alwaysOn>true</alwaysOn>
      <updateRate>0.0</updateRate>
      <cameraName>romr/camera</cameraName>
      <imageTopicName>image_raw</imageTopicName>
      <cameraInfoTopicName>camera_info</cameraInfoTopicName>
      <frameName>camerat265_link</frameName>
      <hackBaseline>0.07</hackBaseline>
      <distortionK1>0.0</distortionK1>
      <distortionK2>0.0</distortionK2>
      <distortionK3>0.0</distortionK3>
      <distortionT1>0.0</distortionT1>
      <distortionT2>0.0</distortionT2>
    </plugin>
  </sensor>
</gazebo> 
  -->
  <gazebo>
    <plugin filename="libgazebo_ros_gps.so" name="gps_plugin">
      <!-- The topic on which the GPS data will be published -->
      <rosTopic>gps/data</rosTopic>
    </plugin>
  </gazebo>
  <gazebo reference="camerad435i_link">
    <sensor name="camerad435i" type="depth">
      <cameraName>d435i</cameraName>
      <always_on>1</always_on>
      <visualize>true</visualize>
      <update_rate>30.0</update_rate>
      <camera>
        <horizontal_fov>1.20428</horizontal_fov>
        <!--RGB sensor FOV (H × V): 69° × 42° -->
        <vertical_fov>0.733038</vertical_fov>
        <image>
          <width>1920</width>
          <height>1080</height>
          <format>R8G8B8</format>
        </image>
        <depth_camera>

      </depth_camera>
        <clip>
          <near>0.02</near>
          <far>30</far>
        </clip>
      </camera>
      <plugin filename="libgazebo_ros_openni_kinect.so" name="camera_controller">
        <alwaysOn>true</alwaysOn>
        <updateRate>30.0</updateRate>
        <!--  <frameName>camera_link_optical</frameName>  -->
        <imageTopicName>rgb/image</imageTopicName>
        <depthImageTopicName>depth/image</depthImageTopicName>
        <cameraInfoTopicName>rgb/camera_info</cameraInfoTopicName>
        <depthImageInfoTopicName>depth/camera_info</depthImageInfoTopicName>
        <pointCloudTopicName>depth/points</pointCloudTopicName>
        <frameName>camera_rgbd_frame</frameName>
        <pointCloudCutoff>0.5</pointCloudCutoff>
        <pointCloudCutoffMax>3.0</pointCloudCutoffMax>
        <hackBaseline>0.07</hackBaseline>
        <distortionK1>0.0</distortionK1>
        <distortionK2>0.0</distortionK2>
        <distortionK3>0.0</distortionK3>
        <distortionT1>0.0</distortionT1>
        <distortionT2>0.0</distortionT2>
        <focalLength>0</focalLength>
        <min_depth>0.001</min_depth>
        <max_depth>100.0</max_depth>
      </plugin>
    </sensor>
  </gazebo>
  <!--******** Define intertial property macros ********** -->
  <!-- ****************** Robot bases ***************************  -->
  <!-- Define the center of the main robot chassis projected on the ground -->
  <link name="base_footprint">
    <inertial>
      <origin rpy="0 0 0" xyz="0 0 0"/>
      <mass value="0"/>
      <inertia ixx="0.0" ixy="0.0" ixz="0.0" iyy="0.0" iyz="0.0" izz="0.0"/>
    </inertial>
  </link>
  <!-- The base footprint of the robot is located underneath the chassis -->
  <joint name="base_joint" type="fixed">
    <parent link="base_link"/>
    <child link="base_footprint"/>
    <origin rpy="0 0 0" xyz="0.0 0.0 -0.14"/>
  </joint>
  <link name="base_link">
    <inertial>
      <origin rpy="0 0 0" xyz="-0.0374777931065171 -0.000742607274570373 0.0517646177576365"/>
      <mass value="5.79174328389446"/>
      <inertia ixx="0.0142969060262334" ixy="-4.92784367063061E-08" ixz="4.92627122966751E-05" iyy="0.0341323035296294" iyz="-2.71693609467846E-08" izz="0.0398544878636473"/>
    </inertial>
    <visual>
      <origin rpy="0 0 0" xyz="0 0 0"/>
      <geometry>
        <mesh filename="package://romr_description/meshes/base_link.STL"/>
      </geometry>
      <material name="white">
      </material>
    </visual>
    <collision>
      <origin rpy="0 0 0" xyz="0 0 0"/>
      <geometry>
        <mesh filename="package://romr_description/meshes/base_link.STL"/>
      </geometry>
    </collision>
  </link>
  <link name="rightwheel_link">
    <inertial>
      <origin rpy="0 0 0" xyz="-1.2143E-17 0.033904 1.3878E-17"/>
      <mass value="1.0582"/>
      <inertia ixx="0.0018538" ixy="-1.2518E-19" ixz="-7.2208E-20" iyy="0.0031139" iyz="1.5395E-18" izz="0.0018538"/>
    </inertial>
    <visual>
      <origin rpy="0 0 0" xyz="0 0 0"/>
      <geometry>
        <mesh filename="package://romr_description/meshes/rightwheel.STL"/>
      </geometry>
      <material name="black">
      </material>
    </visual>
    <collision>
      <origin rpy="0 0 0" xyz="0 0 0"/>
      <geometry>
        <mesh filename="package://romr_description/meshes/rightwheel.STL"/>
      </geometry>
    </collision>
  </link>
  <joint name="rightwheel_joint" type="continuous">
    <origin rpy="0 0 3.1416" xyz="-0.12418 0.185 -0.063"/>
    <parent link="base_link"/>
    <child link="rightwheel_link"/>
    <axis xyz="0 1 0"/>
  </joint>
  <link name="leftwheel_link">
    <inertial>
      <origin rpy="0 0 0" xyz="-2.4286E-17 -0.033904 4.1633E-17"/>
      <mass value="1.0582"/>
      <inertia ixx="0.0018538" ixy="8.3854E-19" ixz="9.7745E-20" iyy="0.0031139" iyz="1.3019E-19" izz="0.0018538"/>
    </inertial>
    <visual>
      <origin rpy="0 0 0" xyz="0 0 0"/>
      <geometry>
        <mesh filename="package://romr_description/meshes/leftwheel.STL"/>
      </geometry>
      <material name="black">
      </material>
    </visual>
    <collision>
      <origin rpy="0 0 0" xyz="0 0 0"/>
      <geometry>
        <mesh filename="package://romr_description/meshes/leftwheel.STL"/>
      </geometry>
    </collision>
  </link>
  <joint name="leftwheel_joint" type="continuous">
    <origin rpy="0 0 -3.1416" xyz="-0.12418 -0.185 -0.063"/>
    <parent link="base_link"/>
    <child link="leftwheel_link"/>
    <axis xyz="0 1 0"/>
  </joint>
  <link name="casterwheel_link">
    <inertial>
      <origin rpy="0 0 0" xyz="-0.0032546 0.0053327 0.013127"/>
      <mass value="0.10255"/>
      <inertia ixx="9.4829E-05" ixy="-2.3412E-06" ixz="1.3145E-05" iyy="0.00012884" iyz="8.5135E-07" izz="5.2207E-05"/>
    </inertial>
    <visual>
      <origin rpy="0 0 0" xyz="0 0 0"/>
      <geometry>
        <mesh filename="package://romr_description/meshes/casterwheel.STL"/>
      </geometry>
      <material name="blue">
      </material>
    </visual>
    <collision>
      <origin rpy="0 0 0" xyz="0 0 0"/>
      <geometry>
        <mesh filename="package://romr_description/meshes/casterwheel.STL"/>
      </geometry>
    </collision>
  </link>
  <joint name="casterwheel_joint" type="fixed">
    <origin rpy="0 0 0" xyz="0.25029 -0.01098 -0.1075"/>
    <parent link="base_link"/>
    <child link="casterwheel_link"/>
    <axis xyz="0 0 0"/>
  </joint>
  <link name="lidar_link">
    <inertial>
      <origin rpy="0 0 0" xyz="0.00050486 -3.7855E-05 -0.025753"/>
      <mass value="0.2064"/>
      <inertia ixx="0.00011156" ixy="-1.2701E-07" ixz="-1.6019E-06" iyy="0.00010988" iyz="1.201E-07" izz="0.0001391"/>
    </inertial>
    <visual>
      <origin rpy="0 0 0" xyz="0 0 0"/>
      <geometry>
        <mesh filename="package://romr_description/meshes/lidar.STL"/>
      </geometry>
      <material name="grey">
      </material>
    </visual>
    <collision>
      <origin rpy="0 0 0" xyz="0 0 0"/>
      <geometry>
        <mesh filename="package://romr_description/meshes/lidar.STL"/>
      </geometry>
    </collision>
  </link>
  <joint name="lidar_joint" type="fixed">
    <origin rpy="0 0 0" xyz="0.00082049 0.00875 0.12332"/>
    <parent link="base_link"/>
    <child link="lidar_link"/>
    <axis xyz="0 0 1"/>
  </joint>
  <link name="imu_link">
    <inertial>
      <origin rpy="0 0 0" xyz="-0.015015 -0.00012812 0.00021369"/>
      <mass value="0.05157"/>
      <inertia ixx="1.5728E-05" ixy="-1.2026E-09" ixz="1.5815E-09" iyy="8.9379E-06" iyz="-2.1887E-10" izz="1.4344E-05"/>
    </inertial>
    <visual>
      <origin rpy="0 0 0" xyz="0 0 0"/>
      <geometry>
        <mesh filename="package://romr_description/meshes/imu.STL"/>
      </geometry>
      <material name="black">
      </material>
    </visual>
    <collision>
      <origin rpy="0 0 0" xyz="0 0 0"/>
      <geometry>
        <mesh filename="package://romr_description/meshes/imu.STL"/>
      </geometry>
    </collision>
  </link>
  <joint name="imu_joint" type="fixed">
    <origin rpy="0 0 0" xyz="0.05082 -0.0047896 0.053918"/>
    <parent link="base_link"/>
    <child link="imu_link"/>
    <axis xyz="0 0 0"/>
  </joint>
  <link name="camerad435i_link">
    <inertial>
      <origin rpy="0 0 0" xyz="0.0094812 3.7095E-05 -7.9734E-05"/>
      <mass value="0.032264"/>
      <inertia ixx="2.2098E-05" ixy="-1.4651E-10" ixz="2.902E-10" iyy="1.9467E-06" iyz="8.3417E-11" izz="2.1858E-05"/>
    </inertial>
    <visual>
      <origin rpy="0 0 0" xyz="0 0 0"/>
      <geometry>
        <mesh filename="package://romr_description/meshes/camerad435i.STL"/>
      </geometry>
      <material name="white">
      </material>
    </visual>
    <collision>
      <origin rpy="0 0 0" xyz="0 0 0"/>
      <geometry>
        <mesh filename="package://romr_description/meshes/camerad435i.STL"/>
      </geometry>
    </collision>
  </link>
  <joint name="camerad435i_joint" type="fixed">
    <origin rpy="0 0 0" xyz="-0.20718 -0.08268 0.17016"/>
    <parent link="base_link"/>
    <child link="camerad435i_link"/>
    <axis xyz="0 0 0"/>
  </joint>
  <link name="camerat265_link">
    <inertial>
      <origin rpy="0 0 0" xyz="0.0061266 3.8568E-05 -1.9004E-05"/>
      <mass value="0.030988"/>
      <inertia ixx="3.0221E-05" ixy="-1.6541E-10" ixz="4.8935E-11" iyy="1.9363E-06" iyz="9.2265E-11" izz="2.9002E-05"/>
    </inertial>
    <visual>
      <origin rpy="0 0 0" xyz="0 0 0"/>
      <geometry>
        <mesh filename="package://romr_description/meshes/camerat265.STL"/>
      </geometry>
      <material name="white">
      </material>
    </visual>
    <collision>
      <origin rpy="0 0 0" xyz="0 0 0"/>
      <geometry>
        <mesh filename="package://romr_description/meshes/camerat265.STL"/>
      </geometry>
    </collision>
  </link>
  <joint name="camerat265_joint" type="fixed">
    <origin rpy="0 0 0" xyz="-0.20118 0.080908 0.16952"/>
    <parent link="base_link"/>
    <child link="camerat265_link"/>
    <axis xyz="0 0 0"/>
  </joint>
</robot>
